<?xml version="1.0"?>
<robot name="greenbot">
   
    <material name="grey">
        <color rgba="0.2 0.2 0.2 1"/>
    </material>

    <material name="white">
        <color rgba="1 1 1 1"/>
    </material>

    <material name="blue">
        <color rgba="0 0 1 1"/>
    </material>

    <material name="yellow">
        <color rgba="240 255 0 1"/>
    </material>


   <!-- base link -->
    <link name="base_link"></link>

    <!--  -->
    <joint name="base_to_undercarriage" type="fixed">
        <parent link="base_link" />
        <child link="undercarriage" />
        <origin xyz="-0.3 0 0.08" rpy="0 0 0"/>
    </joint>

   <!-- undercarriage -->
    <link name="undercarriage">
        <visual>
            <origin xyz="0.0 0 0.0" rpy="0 0 0"/>
            <geometry>
                <box size="0.9 0.5 0.05" />
            </geometry>
            <material name="white"/>
        </visual>

        <collision>
            <origin xyz="0.0 0 0.0" rpy="0 0 0"/>
            <geometry>
                <box size="0.9 0.5 0.05" />
            </geometry>
        </collision>

        <inertial>
           <mass value="10"/>
           <origin xyz="0 0 0" rpy="0 0 0"/>
           <inertia ixx="0.13" ixy="0.0" ixz="0.0" iyy="8.1" iyz="0.0" izz="0.13"/>   
        </inertial>
    </link>

    <!-- left wheel -->
    <link name="left_wheel">
        <visual>
            <origin xyz="0.0 0 0.025" rpy="0 0 0"/>
            <geometry>
                <cylinder radius="0.1" length="0.05"/>
            </geometry>
            <material name="blue"/>
        </visual>

        <collision>
            <origin xyz="0.0 0 0.025" rpy="0 0 0"/>
            <geometry>
                <cylinder radius="0.1" length="0.05"/>
            </geometry>
        </collision>

        <inertial>
           <mass value="2"/>
           <origin xyz="0 0 0" rpy="0 0 0"/>
           <inertia ixx="0.13" ixy="0.0" ixz="0.0" iyy="8.1" iyz="0.0" izz="0.13"/>   
        </inertial>
    </link>

    <!-- left wheel joint -->
    <joint name="left_wheel_joint" type="continuous">
        <parent link="base_link"/>
        <child link="left_wheel"/>
        <origin xyz="0 0.25 0" rpy="-1.57079 0 0" />
        <axis xyz="0 0 1"/>
    </joint>

    <!-- right wheel -->
    <link name="right_wheel">
        <visual>
            <origin xyz="0.0 0 -0.025" rpy="0 0 0"/>
            <geometry>
                <cylinder radius="0.1" length="0.05"/>
            </geometry>
            <material name="blue"/>
        </visual>

        <collision>
            <origin xyz="0.0 0 -0.025" rpy="0 0 0"/>
            <geometry>
                <cylinder radius="0.1" length="0.05"/>
            </geometry>
        </collision>

        <inertial>
           <mass value="2"/>
           <origin xyz="0 0 0" rpy="0 0 0"/>
           <inertia ixx="0.13" ixy="0.0" ixz="0.0" iyy="8.1" iyz="0.0" izz="0.13"/>   
        </inertial>
    </link>

    <!-- left wheel joint -->
    <joint name="right_wheel_joint" type="continuous">
        <parent link="base_link"/>
        <child link="right_wheel"/>
        <origin xyz="0 -0.25 0" rpy="-1.57079 0 0" />
        <axis xyz="0 0 1"/>
    </joint>

     <!-- left omni wheel -->
    <link name="left_omni_wheel">
        <visual>
            <origin xyz="0.0 0 0.025" rpy="0 0 0"/>
            <geometry>
                <cylinder radius="0.1" length="0.05"/>
            </geometry>
            <material name="gray"/>
        </visual>

        <collision>
            <origin xyz="0.0 0 0.025" rpy="0 0 0"/>
            <geometry>
                <cylinder radius="0.1" length="0.05"/>
            </geometry>
        </collision>

        <inertial>
           <mass value="2"/>
           <origin xyz="0 0 0" rpy="0 0 0"/>
           <inertia ixx="0.13" ixy="0.0" ixz="0.0" iyy="8.1" iyz="0.0" izz="0.13"/>   
        </inertial>
    </link>

    <!-- left omniwheel joint -->
    <joint name="left_omniwheel_joint" type="fixed">
        <parent link="base_link"/>
        <child link="left_omni_wheel"/>
        <origin xyz="-0.6 0.25 0" rpy="-1.57079 0 0" />
        <axis xyz="0 0 1"/>
    </joint>

     <!-- right omni wheel -->
    <link name="right_omni_wheel">
        <visual>
            <origin xyz="0.0 0 -0.025" rpy="0 0 0"/>
            <geometry>
                <cylinder radius="0.1" length="0.05"/>
            </geometry>
            <material name="grey"/>
        </visual>

        <collision>
            <origin xyz="0.0 0 -0.025" rpy="0 0 0"/>
            <geometry>
                <cylinder radius="0.1" length="0.05"/>
            </geometry>
        </collision>

        <inertial>
           <mass value="2"/>
           <origin xyz="0 0 0" rpy="0 0 0"/>
           <inertia ixx="0.13" ixy="0.0" ixz="0.0" iyy="8.1" iyz="0.0" izz="0.13"/>   
        </inertial>
    </link>

    <!-- left omni wheel joint -->
    <joint name="right_omniwheel_joint" type="fixed">
        <parent link="base_link"/>
        <child link="right_omni_wheel"/>
        <origin xyz="-0.6 -0.25 0" rpy="-1.57079 0 0" />
        <axis xyz="0 0 1"/>
    </joint>



    <!-- lidar 1 -->
    <link name="sick_nanoscan3_s1">
        <visual>
            <origin xyz="0.0 0 0.0" rpy="0 0 0"/>
            <geometry>
                <box size="0.1 0.1 0.08" />
            </geometry>
             <material name="yellow"/>
        </visual>

        <collision>
            <origin xyz="0.0 0 0.0" rpy="0 0 0"/>
            <geometry>
                <box size="0.1 0.1 0.08" />
            </geometry>
        </collision>

        <inertial>
           <mass value="1"/>
           <origin xyz="0.0 0 0.0" rpy="0 0 0"/>
           <inertia ixx="1" ixy="0.0" ixz="0.0" iyy="0.01" iyz="0.0" izz="0.01"/>   
        </inertial>
    </link>

    <joint name="sick_s1_joint" type="fixed">
        <origin xyz="0.08 0.18 0.15" rpy="0.0 0.0 -0.785398"/>
        <parent link="base_link"/>
        <child link="sick_nanoscan3_s1"/>
    </joint>

     <!-- lidar 2-->
    <link name="sick_nanoscan3_s2">
        <visual>
            <origin xyz="0.0 0 0.0" rpy="0 0 0"/>
            <geometry>
                <box size="0.1 0.1 0.08" />
            </geometry>
             <material name="yellow"/>
        </visual>

        <collision>
            <origin xyz="0.0 0 0.0" rpy="0 0 0"/>
            <geometry>
                <box size="0.1 0.1 0.08" />
            </geometry>
        </collision>

        <inertial>
           <mass value="1"/>
           <origin xyz="0.0 0 0.0" rpy="0 0 0"/>
           <inertia ixx="1" ixy="0.0" ixz="0.0" iyy="0.01" iyz="0.0" izz="0.01"/>   
        </inertial>
    </link>

    <joint name="sick_s2_joint" type="fixed">
        <origin xyz="-0.68 -0.18 0.15" rpy="0.0 0.0 2.356194"/>
        <parent link="base_link"/>
        <child link="sick_nanoscan3_s2"/>
    </joint>

    <!-- top cover -->
    <link name="top_cover">
        <visual>
            <origin xyz="0.0 0 0.0" rpy="0 0 0"/>
            <geometry>
                <box size="0.9 0.6 0.03" />
            </geometry>
             <material name="white"/>
        </visual>

        <collision>
            <origin xyz="0.0 0 0.0" rpy="0 0 0"/>
            <geometry>
                <box size="0.9 0.6 0.03" />
            </geometry>
        </collision>

        <inertial>
           <mass value="16"/>
           <origin xyz="0.0 0 0.0" rpy="0 0 0"/>
           <inertia ixx="1" ixy="0.0" ixz="0.0" iyy="0.01" iyz="0.0" izz="0.01"/>   
        </inertial>
    </link>

    <joint name="top2base" type="fixed">
        <origin xyz="-0.3 0.0 0.27" rpy="0.0 0.0 0.0"/>
        <parent link="base_link"/>
        <child link="top_cover"/>
    </joint>


<!-- battery -->
    <link name="battery">
        <visual>
            <origin xyz="0.0 0 0.0" rpy="0 0 0"/>
            <geometry>
                <box size="0.5 0.3 0.18" />
            </geometry>
             <material name="white"/>
        </visual>

        <collision>
            <origin xyz="0.0 0 0.0" rpy="0 0 0"/>
            <geometry>
                <box size="0.5 0.3 0.17"/>
            </geometry>
        </collision>

        <inertial>
           <mass value="16"/>
           <origin xyz="0.0 0 0.0" rpy="0 0 0"/>
           <inertia ixx="1" ixy="0.0" ixz="0.0" iyy="0.01" iyz="0.0" izz="0.01"/>   
        </inertial>
    </link>

    <joint name="bat2base" type="fixed">
        <origin xyz="-0.3 0.0 0.19" rpy="0.0 0.0 0.0"/>
        <parent link="base_link"/>
        <child link="battery"/>
    </joint>

    <!-- GAZEBO -->
    <!-- material -->
    <gazebo reference="undercarriage">
        <material>Gazebo/White</material>
    </gazebo>

    <gazebo reference="top_cover">
        <material>Gazebo/White</material>
    </gazebo>

    <gazebo reference="left_wheel">
        <material>Gazebo/Blue</material>
    </gazebo>

    <gazebo reference="right_wheel">
        <material>Gazebo/Blue</material>
    </gazebo>

    <gazebo reference="left_omni_wheel">
        <material>Gazebo/Gray</material>
        <mu1 value="0.001"/>
        <mu2 value="0.001"/>
    </gazebo>

    <gazebo reference="right_omni_wheel">
        <material>Gazebo/Gray</material>
        <mu1 value="0.001"/>
        <mu2 value="0.001"/>
    </gazebo>

    <!-- ros_control plugin -->


    <gazebo>
  <plugin name="differential_drive_controller" filename="libgazebo_ros_diff_drive.so">

    <!-- Plugin update rate in Hz -->
    <updateRate>50</updateRate>

    <robotNamespace>/</robotNamespace>

    <!-- Name of left joint, defaults to `left_joint` -->
    <leftJoint>left_wheel_joint</leftJoint>
    <!-- Name of right joint, defaults to `right_joint` -->
    <rightJoint>right_wheel_joint</rightJoint>

    <!-- The distance from the center of one wheel to the other, in meters, defaults to 0.34 m -->
    <wheelSeparation>0.55</wheelSeparation>

    <!-- Diameter of the wheels, in meters, defaults to 0.15 m -->
    <wheelDiameter>0.2</wheelDiameter>

    <!-- Wheel acceleration, in rad/s^2, defaults to 0.0 rad/s^2 -->
    <wheelAcceleration>5.0</wheelAcceleration>

    <!-- Maximum torque which the wheels can produce, in Nm, defaults to 5 Nm -->
    <wheelTorque>20</wheelTorque>

    <!-- Topic to receive geometry_msgs/Twist message commands, defaults to `cmd_vel` -->
    <commandTopic>safe_vel</commandTopic>

    <!-- Topic to publish nav_msgs/Odometry messages, defaults to `odom` -->
    <odometryTopic>odom</odometryTopic>

    <!-- Odometry frame, defaults to `odom` -->
    <odometryFrame>odom</odometryFrame>

    <!-- Robot frame to calculate odometry from, defaults to `base_footprint` -->
    <robotBaseFrame>base_link</robotBaseFrame>

    <!-- Odometry source, 0 for ENCODER, 1 for WORLD, defaults to WORLD -->
    <odometrySource>1</odometrySource>

    <!-- Set to true to publish transforms for the wheel links, defaults to false -->
    <publishWheelTF>true</publishWheelTF>

    <!-- Set to true to publish transforms for the odometry, defaults to true -->
    <publishOdomTF>true</publishOdomTF>

    <!-- Set to true to publish sensor_msgs/JointState on /joint_states for the wheel joints, defaults to false -->
    <publishWheelJointState>true</publishWheelJointState>

    <!-- Set to true to swap right and left wheels, defaults to true -->
    <legacyMode>false</legacyMode>
  </plugin>
</gazebo>

    <!-- gazebo joint state publisher -->
    <!-- <gazebo>
        <plugin name="joint_state_publisher" filename="libgazebo_ros_joint_state_publisher.so">
            <robotNamespace>/greenbot</robotNamespace>
            <jointName>left_wheel_joint, right_wheel_joint</jointName>
            <updateRate>50</updateRate>
        </plugin>
    </gazebo>  -->

    <!-- simuliraj lidar s1-->
    <gazebo reference="sick_nanoscan3_s1">
        <material>Gazebo/Yellow</material>
        <sensor type="ray" name="SICK_lidar_s1">
            <pose>0 0 0 0 0 0</pose>
            <visualize>true</visualize>
            <update_rate>25</update_rate>
            <ray>
                <scan>
                    <horizontal>
                        <samples>1571</samples>
                        <resolution>1</resolution>
                        <min_angle>-0.7853</min_angle>
                        <max_angle>3.926</max_angle>
                    </horizontal>
                </scan>
                <range>
                    <min>0.15</min>
                    <max>2.0</max>
                    <resolution>0.01</resolution>
                </range>
                <noise>
                    <type>gaussian</type>
                     <!-- Noise parameters based on published spec for Hokuyo laser
                    achieving "+-30mm" accuracy at range < 10m.  A mean of 0.0m and
                    stddev of 0.01m will put 99.7% of samples within 0.03m of the true
                    reading. -->
                    <mean>0.0</mean>
                    <stddev>0.01</stddev>
                </noise>
            </ray>
            <plugin name="laser_controller" filename="libgazebo_ros_laser.so">
                <topicName>/scanner1/sick_safetyscanners/scan</topicName>
                <frameName>sick_nanoscan3_s1</frameName>
            </plugin>
        </sensor>
    </gazebo>

     <!-- simuliraj lidar s2-->
    <gazebo reference="sick_nanoscan3_s2">
        <material>Gazebo/Yellow</material>
        <sensor type="ray" name="SICK_lidar_s2">
            <pose>0 0 0 0 0 0</pose>
            <visualize>false</visualize>
            <update_rate>25</update_rate>
            <ray>
                <scan>
                    <horizontal>
                        <samples>1571</samples>
                        <resolution>1</resolution>
                        <min_angle>-0.785</min_angle>
                        <max_angle>3.926</max_angle>
                    </horizontal>
                </scan>
                <range>
                    <min>0.15</min>
                    <max>2.0</max>
                    <resolution>0.01</resolution>
                </range>
                <noise>
                    <type>gaussian</type>-->
                     <!-- Noise parameters based on published spec for Hokuyo laser
                    achieving "+-30mm" accuracy at range < 10m.  A mean of 0.0m and
                    stddev of 0.01m will put 99.7% of samples within 0.03m of the true
                    reading. -->
                    <mean>0.0</mean>
                    <stddev>0.01</stddev>
                </noise>
            </ray>
            <plugin name="laser_controller" filename="libgazebo_ros_laser.so">
                <topicName>/scanner2/sick_safetyscanners/scan</topicName>
                <frameName>sick_nanoscan3_s2</frameName>
            </plugin>
        </sensor>
    </gazebo> 

    

</robot>